[2025-01-17T09:25:51.468+0000] {local_task_job_runner.py:123} INFO - ::group::Pre task execution logs
[2025-01-17T09:25:51.504+0000] {taskinstance.py:2613} INFO - Dependencies all met for dep_context=non-requeueable deps ti=<TaskInstance: cryptobot_workflow.fetch_data scheduled__2025-01-17T04:00:00+00:00 [queued]>
[2025-01-17T09:25:51.518+0000] {taskinstance.py:2613} INFO - Dependencies all met for dep_context=requeueable deps ti=<TaskInstance: cryptobot_workflow.fetch_data scheduled__2025-01-17T04:00:00+00:00 [queued]>
[2025-01-17T09:25:51.519+0000] {taskinstance.py:2866} INFO - Starting attempt 1 of 1
[2025-01-17T09:25:53.395+0000] {taskinstance.py:2889} INFO - Executing <Task(BashOperator): fetch_data> on 2025-01-17 04:00:00+00:00
[2025-01-17T09:25:53.441+0000] {warnings.py:112} WARNING - /home/***/.local/lib/python3.12/site-packages/***/task/task_runner/standard_task_runner.py:70: DeprecationWarning: This process (pid=139) is multi-threaded, use of fork() may lead to deadlocks in the child.
  pid = os.fork()

[2025-01-17T09:25:53.445+0000] {standard_task_runner.py:72} INFO - Started process 147 to run task
[2025-01-17T09:25:53.449+0000] {standard_task_runner.py:104} INFO - Running: ['***', 'tasks', 'run', 'cryptobot_workflow', 'fetch_data', 'scheduled__2025-01-17T04:00:00+00:00', '--job-id', '3', '--raw', '--subdir', 'DAGS_FOLDER/cryptobot_dag.py', '--cfg-path', '/tmp/tmp820tr8zn']
[2025-01-17T09:25:53.452+0000] {standard_task_runner.py:105} INFO - Job 3: Subtask fetch_data
[2025-01-17T09:25:53.725+0000] {task_command.py:467} INFO - Running <TaskInstance: cryptobot_workflow.fetch_data scheduled__2025-01-17T04:00:00+00:00 [running]> on host ae5d752becfe
[2025-01-17T09:25:53.815+0000] {taskinstance.py:3132} INFO - Exporting env vars: AIRFLOW_CTX_DAG_OWNER='***' AIRFLOW_CTX_DAG_ID='cryptobot_workflow' AIRFLOW_CTX_TASK_ID='fetch_data' AIRFLOW_CTX_EXECUTION_DATE='2025-01-17T04:00:00+00:00' AIRFLOW_CTX_TRY_NUMBER='1' AIRFLOW_CTX_DAG_RUN_ID='scheduled__2025-01-17T04:00:00+00:00'
[2025-01-17T09:25:53.823+0000] {logging_mixin.py:190} INFO - Task instance is in running state
[2025-01-17T09:25:53.824+0000] {logging_mixin.py:190} INFO -  Previous state of the Task instance: queued
[2025-01-17T09:25:53.825+0000] {logging_mixin.py:190} INFO - Current task name:fetch_data state:running start_date:2025-01-17 09:25:51.506378+00:00
[2025-01-17T09:25:53.826+0000] {logging_mixin.py:190} INFO - Dag name:cryptobot_workflow and current dag run status:running
[2025-01-17T09:25:53.826+0000] {taskinstance.py:731} INFO - ::endgroup::
[2025-01-17T09:25:53.836+0000] {subprocess.py:78} INFO - Tmp dir root location: /tmp
[2025-01-17T09:25:53.838+0000] {subprocess.py:88} INFO - Running command: ['/usr/bin/bash', '-c', 'python ../../src/extract.py']
[2025-01-17T09:25:53.852+0000] {subprocess.py:99} INFO - Output:
[2025-01-17T09:25:53.903+0000] {subprocess.py:106} INFO - python: can't open file '/tmp/***tmpntnhbu74/../../src/extract.py': [Errno 2] No such file or directory
[2025-01-17T09:25:53.907+0000] {subprocess.py:110} INFO - Command exited with return code 2
[2025-01-17T09:25:53.923+0000] {taskinstance.py:3311} ERROR - Task failed with exception
Traceback (most recent call last):
  File "/home/airflow/.local/lib/python3.12/site-packages/airflow/models/taskinstance.py", line 767, in _execute_task
    result = _execute_callable(context=context, **execute_callable_kwargs)
             ^^^^^^^^^^^^^^^^^^^^^^^^^^^^^^^^^^^^^^^^^^^^^^^^^^^^^^^^^^^^^
  File "/home/airflow/.local/lib/python3.12/site-packages/airflow/models/taskinstance.py", line 733, in _execute_callable
    return ExecutionCallableRunner(
           ^^^^^^^^^^^^^^^^^^^^^^^^
  File "/home/airflow/.local/lib/python3.12/site-packages/airflow/utils/operator_helpers.py", line 252, in run
    return self.func(*args, **kwargs)
           ^^^^^^^^^^^^^^^^^^^^^^^^^^
  File "/home/airflow/.local/lib/python3.12/site-packages/airflow/models/baseoperator.py", line 422, in wrapper
    return func(self, *args, **kwargs)
           ^^^^^^^^^^^^^^^^^^^^^^^^^^^
  File "/home/airflow/.local/lib/python3.12/site-packages/airflow/operators/bash.py", line 276, in execute
    raise AirflowException(
airflow.exceptions.AirflowException: Bash command failed. The command returned a non-zero exit code 2.
[2025-01-17T09:25:53.931+0000] {logging_mixin.py:190} INFO - Task instance in failure state
[2025-01-17T09:25:53.931+0000] {logging_mixin.py:190} INFO - Task start:2025-01-17 09:25:51.506378+00:00 end:2025-01-17 09:25:53.930360+00:00 duration:2.423982
[2025-01-17T09:25:53.931+0000] {logging_mixin.py:190} INFO - Task:<Task(BashOperator): fetch_data> dag:<DAG: cryptobot_workflow> dagrun:<DagRun cryptobot_workflow @ 2025-01-17 04:00:00+00:00: scheduled__2025-01-17T04:00:00+00:00, state:running, queued_at: 2025-01-17 09:25:40.320232+00:00. externally triggered: False>
[2025-01-17T09:25:53.932+0000] {logging_mixin.py:190} INFO - Failure caused by Bash command failed. The command returned a non-zero exit code 2.
[2025-01-17T09:25:53.932+0000] {taskinstance.py:1225} INFO - Marking task as FAILED. dag_id=cryptobot_workflow, task_id=fetch_data, run_id=scheduled__2025-01-17T04:00:00+00:00, execution_date=20250117T040000, start_date=20250117T092551, end_date=20250117T092553
[2025-01-17T09:25:53.945+0000] {taskinstance.py:340} INFO - ::group::Post task execution logs
[2025-01-17T09:25:53.946+0000] {standard_task_runner.py:124} ERROR - Failed to execute job 3 for task fetch_data (Bash command failed. The command returned a non-zero exit code 2.; 147)
Traceback (most recent call last):
  File "/home/airflow/.local/lib/python3.12/site-packages/airflow/task/task_runner/standard_task_runner.py", line 117, in _start_by_fork
    ret = args.func(args, dag=self.dag)
          ^^^^^^^^^^^^^^^^^^^^^^^^^^^^^
  File "/home/airflow/.local/lib/python3.12/site-packages/airflow/cli/cli_config.py", line 49, in command
    return func(*args, **kwargs)
           ^^^^^^^^^^^^^^^^^^^^^
  File "/home/airflow/.local/lib/python3.12/site-packages/airflow/utils/cli.py", line 116, in wrapper
    return f(*args, **kwargs)
           ^^^^^^^^^^^^^^^^^^
  File "/home/airflow/.local/lib/python3.12/site-packages/airflow/cli/commands/task_command.py", line 483, in task_run
    task_return_code = _run_task_by_selected_method(args, _dag, ti)
                       ^^^^^^^^^^^^^^^^^^^^^^^^^^^^^^^^^^^^^^^^^^^^
  File "/home/airflow/.local/lib/python3.12/site-packages/airflow/cli/commands/task_command.py", line 256, in _run_task_by_selected_method
    return _run_raw_task(args, ti)
           ^^^^^^^^^^^^^^^^^^^^^^^
  File "/home/airflow/.local/lib/python3.12/site-packages/airflow/cli/commands/task_command.py", line 341, in _run_raw_task
    return ti._run_raw_task(
           ^^^^^^^^^^^^^^^^^
  File "/home/airflow/.local/lib/python3.12/site-packages/airflow/utils/session.py", line 97, in wrapper
    return func(*args, session=session, **kwargs)
           ^^^^^^^^^^^^^^^^^^^^^^^^^^^^^^^^^^^^^^
  File "/home/airflow/.local/lib/python3.12/site-packages/airflow/models/taskinstance.py", line 3005, in _run_raw_task
    return _run_raw_task(
           ^^^^^^^^^^^^^^
  File "/home/airflow/.local/lib/python3.12/site-packages/airflow/models/taskinstance.py", line 273, in _run_raw_task
    TaskInstance._execute_task_with_callbacks(
  File "/home/airflow/.local/lib/python3.12/site-packages/airflow/models/taskinstance.py", line 3159, in _execute_task_with_callbacks
    result = self._execute_task(context, task_orig)
             ^^^^^^^^^^^^^^^^^^^^^^^^^^^^^^^^^^^^^^
  File "/home/airflow/.local/lib/python3.12/site-packages/airflow/models/taskinstance.py", line 3183, in _execute_task
    return _execute_task(self, context, task_orig)
           ^^^^^^^^^^^^^^^^^^^^^^^^^^^^^^^^^^^^^^^
  File "/home/airflow/.local/lib/python3.12/site-packages/airflow/models/taskinstance.py", line 767, in _execute_task
    result = _execute_callable(context=context, **execute_callable_kwargs)
             ^^^^^^^^^^^^^^^^^^^^^^^^^^^^^^^^^^^^^^^^^^^^^^^^^^^^^^^^^^^^^
  File "/home/airflow/.local/lib/python3.12/site-packages/airflow/models/taskinstance.py", line 733, in _execute_callable
    return ExecutionCallableRunner(
           ^^^^^^^^^^^^^^^^^^^^^^^^
  File "/home/airflow/.local/lib/python3.12/site-packages/airflow/utils/operator_helpers.py", line 252, in run
    return self.func(*args, **kwargs)
           ^^^^^^^^^^^^^^^^^^^^^^^^^^
  File "/home/airflow/.local/lib/python3.12/site-packages/airflow/models/baseoperator.py", line 422, in wrapper
    return func(self, *args, **kwargs)
           ^^^^^^^^^^^^^^^^^^^^^^^^^^^
  File "/home/airflow/.local/lib/python3.12/site-packages/airflow/operators/bash.py", line 276, in execute
    raise AirflowException(
airflow.exceptions.AirflowException: Bash command failed. The command returned a non-zero exit code 2.
[2025-01-17T09:25:54.002+0000] {local_task_job_runner.py:266} INFO - Task exited with return code 1
[2025-01-17T09:25:54.050+0000] {taskinstance.py:3895} INFO - 0 downstream tasks scheduled from follow-on schedule check
[2025-01-17T09:25:54.056+0000] {local_task_job_runner.py:245} INFO - ::endgroup::
